<?xml version='1.0' encoding='utf-8'?>
<mujoco model="panda"><compiler angle="radian" meshdir="assets" autolimits="true" /><option integrator="implicitfast" /><default><joint armature="0.1" damping="1" axis="0 0 1" range="-2.8973 2.8973" /><default class="arm"><position ctrlrange="-2.8973 2.8973" forcerange="-150 150" kp="500" kv="50" /></default><default class="collision"><geom type="mesh" group="3" /></default><default class="visual"><geom group="2" /></default></default><asset><mesh name="link0_c" file="link0.stl" /><mesh name="link1_c" file="link1.stl" /><mesh name="link2_c" file="link2.stl" /><mesh name="link3_c" file="link3.stl" /><mesh name="link4_c" file="link4.stl" /><mesh name="link6_c" file="link6.stl" /><mesh name="link7_c" file="link7.stl" /><mesh name="link5_c0" file="link5_collision_0.obj" /><mesh name="link5_c1" file="link5_collision_1.obj" /><mesh name="link5_c2" file="link5_collision_2.obj" /><material name="grey" rgba="0.35 0.35 0.35 1" /><material name="white" rgba="0.9 0.9 0.95 1" /><material name="blue" rgba="0.04 0.54 0.78 1" /><material name="dark" rgba="0.25 0.25 0.25 1" /></asset><worldbody><light name="top" pos="0 0 2" mode="trackcom" /><geom name="floor" type="plane" size="0 0 0.05" rgba="0.2 0.3 0.4 1" /><body name="link0" childclass="arm"><inertial mass="0.629769" pos="-0.041018 -0.000140 0.049974" diaginertia="0.003150 0.003880 0.004285" /><geom type="cylinder" size="0.12 0.1665" material="dark" class="visual" /><geom class="collision" mesh="link0_c" /><body name="link1" pos="0 0 0.333" childclass="arm"><joint name="joint1" /><inertial mass="4.970684" pos="0.003875 0.002081 -0.047620" diaginertia="0.703370 0.706610 0.009117" /><geom type="cylinder" size="0.08 0.04" material="white" class="visual" /><geom class="collision" mesh="link1_c" /><body name="link2" quat="1 -1 0 0" childclass="arm"><joint name="joint2" range="-1.7628 1.7628" /><inertial mass="0.646926" pos="-0.003141 -0.028720 0.003495" diaginertia="0.007962 0.028110 0.025995" /><geom type="capsule" size="0.065" material="grey" class="visual" fromto="0 0 0  0 0.316 0" /><geom class="collision" mesh="link2_c" /><body name="link3" pos="0 0.316 0" quat="1 1 0 0" childclass="arm"><joint name="joint3" /><inertial mass="3.228604" pos="0.027518 0.039252 -0.066502" diaginertia="0.037242 0.036155 0.010830" /><geom type="capsule" size="0.065" material="white" class="visual" fromto="0 0 0  0.0825 0 0" /><geom class="collision" mesh="link3_c" /><body name="link4" pos="0.0825 0 0" quat="1 1 0 0" childclass="arm"><joint name="joint4" range="-3.0718 -0.0698" /><inertial mass="3.587895" pos="-0.053170 0.104419 0.027454" diaginertia="0.025853 0.019552 0.028323" /><geom type="capsule" size="0.055" material="white" class="visual" fromto="0 0 0  0 0.384 0" /><geom class="collision" mesh="link4_c" /><body name="link5" pos="0 0.384 0" quat="1 -1 0 0" childclass="arm"><joint name="joint5" /><inertial mass="1.225946" pos="-0.011953 0.041065 -0.038437" diaginertia="0.035549 0.029474 0.008627" /><geom type="sphere" size="0.05" material="grey" class="visual" /><geom class="collision" mesh="link5_c0" /><geom class="collision" mesh="link5_c1" /><geom class="collision" mesh="link5_c2" /><body name="link6" quat="1 1 0 0" childclass="arm"><joint name="joint6" range="-0.0175 3.7525" /><inertial mass="1.666555" pos="0.060149 -0.014117 -0.010517" diaginertia="0.001964 0.004354 0.005433" /><geom type="capsule" size="0.045" material="white" class="visual" fromto="0 0 0  0.088 0 0" /><geom class="collision" mesh="link6_c" /><body name="link7" pos="0.088 0 0" quat="1 1 0 0" childclass="arm"><joint name="joint7" /><inertial mass="0.735522" pos="0.010517 -0.004252 0.061597" diaginertia="0.012516 0.010027 0.004815" /><geom type="cylinder" size="0.04 0.04" material="dark" class="visual" /><geom class="collision" mesh="link7_c" /><body name="hand" pos="0 0 0.107" quat="0.9238795 0 0 -0.3826834" childclass="arm"><inertial mass="0.73" pos="-0.010000 0.000000 0.030000" diaginertia="0.001000 0.002500 0.001700" /><geom type="cylinder" size="0.045 0.025" material="grey" class="visual" /><site name="gripper_attach" pos="0 0 0.03" size="0.01 0.01 0.01" type="box" rgba="1 0 0 0.5" group="1" /></body></body></body></body></body></body></body></body></body></worldbody><actuator><position class="arm" name="actuator1" joint="joint1" /><position class="arm" name="actuator2" joint="joint2" /><position class="arm" name="actuator3" joint="joint3" /><position class="arm" name="actuator4" joint="joint4" /><position class="arm" name="actuator5" joint="joint5" /><position class="arm" name="actuator6" joint="joint6" /><position class="arm" name="actuator7" joint="joint7" /></actuator><keyframe><key name="home" qpos="0 0 0 -1.57079 0 1.57079 -0.7853" ctrl="0 0 0 -1.57079 0 1.57079 -0.7853" /></keyframe></mujoco>