<mujoco model="franka_tendon_pick_place">
  <compiler angle="radian" meshdir="../assets" autolimits="true"/>

  <option integrator="implicitfast" timestep="0.00025"
          cone="elliptic" impratio="10.0"/>

  <default>
    <default class="panda">
      <material specular="0.5" shininess="0.25"/>
      <joint armature="0.1" damping="1" axis="0 0 1" range="-2.8973 2.8973"/>
      <general dyntype="none" biastype="affine" ctrlrange="-2.8973 2.8973" forcerange="-87 87"/>
      <default class="visual">
        <geom type="mesh" contype="0" conaffinity="0" group="2"/>
      </default>
      <default class="collision">
        <geom type="mesh" group="3"/>
      </default>
    </default>

    <geom condim="6" friction="0.4 0.1 0.01"
          solref="0.0005 1" solimp="0.99 0.9999 0.0001 0.5 2"
          density="0"/>
    <joint type="hinge" axis="0 0 1" damping="0.08" limited="true"
           solreflimit="0.002 1" solimplimit="0.99 0.9999 0.0001 0.5 2"/>
    <default class="phalanx_vis">
      <geom type="mesh" rgba="0.78 0.80 0.85 1" contype="0" conaffinity="0"/>
    </default>
    <default class="phalanx_pad">
      <geom type="box" contype="1" conaffinity="1" friction="6.0 6.0 0.05"
            solref="0.008 0.5" solimp="0.3 0.9 0.01 0.3 2"/>
    </default>
    <site group="3"/>
  </default>

  <asset>
    <!-- Franka collision meshes -->
    <mesh name="link0_c" file="link0.stl"/>
    <mesh name="link1_c" file="link1.stl"/>
    <mesh name="link2_c" file="link2.stl"/>
    <mesh name="link3_c" file="link3.stl"/>
    <mesh name="link4_c" file="link4.stl"/>
    <mesh name="link5_c0" file="link5_collision_0.obj"/>
    <mesh name="link5_c1" file="link5_collision_1.obj"/>
    <mesh name="link5_c2" file="link5_collision_2.obj"/>
    <mesh name="link6_c" file="link6.stl"/>
    <mesh name="link7_c" file="link7.stl"/>
    <mesh name="hand_c" file="hand.stl"/>

    <!-- Franka visual meshes -->
    <mesh file="link0_0.obj"/>
    <mesh file="link0_1.obj"/>
    <mesh file="link0_2.obj"/>
    <mesh file="link0_3.obj"/>
    <mesh file="link0_4.obj"/>
    <mesh file="link0_5.obj"/>
    <mesh file="link0_7.obj"/>
    <mesh file="link0_8.obj"/>
    <mesh file="link0_9.obj"/>
    <mesh file="link0_10.obj"/>
    <mesh file="link0_11.obj"/>
    <mesh file="link1.obj"/>
    <mesh file="link2.obj"/>
    <mesh file="link3_0.obj"/>
    <mesh file="link3_1.obj"/>
    <mesh file="link3_2.obj"/>
    <mesh file="link3_3.obj"/>
    <mesh file="link4_0.obj"/>
    <mesh file="link4_1.obj"/>
    <mesh file="link4_2.obj"/>
    <mesh file="link4_3.obj"/>
    <mesh file="link5_0.obj"/>
    <mesh file="link5_1.obj"/>
    <mesh file="link5_2.obj"/>
    <mesh file="link6_0.obj"/>
    <mesh file="link6_1.obj"/>
    <mesh file="link6_2.obj"/>
    <mesh file="link6_3.obj"/>
    <mesh file="link6_4.obj"/>
    <mesh file="link6_5.obj"/>
    <mesh file="link6_6.obj"/>
    <mesh file="link6_7.obj"/>
    <mesh file="link6_8.obj"/>
    <mesh file="link6_9.obj"/>
    <mesh file="link6_10.obj"/>
    <mesh file="link6_11.obj"/>
    <mesh file="link6_12.obj"/>
    <mesh file="link6_13.obj"/>
    <mesh file="link6_14.obj"/>
    <mesh file="link6_15.obj"/>
    <mesh file="link6_16.obj"/>
    <mesh file="link7_0.obj"/>
    <mesh file="link7_1.obj"/>
    <mesh file="link7_2.obj"/>
    <mesh file="link7_3.obj"/>
    <mesh file="link7_4.obj"/>
    <mesh file="link7_5.obj"/>
    <mesh file="link7_6.obj"/>
    <mesh file="link7_7.obj"/>
    <mesh file="hand_0.obj"/>
    <mesh file="hand_1.obj"/>
    <mesh file="hand_2.obj"/>
    <mesh file="hand_3.obj"/>
    <mesh file="hand_4.obj"/>

    <!-- Gripper phalanx meshes -->
    <mesh name="proximal_mesh" file="../../high_fidelity/meshes/proximal.stl"/>
    <mesh name="middle_mesh"   file="../../high_fidelity/meshes/middle.stl"/>
    <mesh name="distal_mesh"   file="../../high_fidelity/meshes/distal.stl"/>

    <!-- Materials & textures -->
    <material class="panda" name="white" rgba="0.9 0.9 0.95 1"/>
    <material class="panda" name="off_white" rgba="0.902 0.922 0.929 1"/>
    <material class="panda" name="black" rgba="0.25 0.25 0.25 1"/>
    <material class="panda" name="green" rgba="0 1 0 1"/>
    <material class="panda" name="light_blue" rgba="0.039 0.541 0.780 1"/>
    <texture type="skybox" builtin="gradient" rgb1="0.3 0.5 0.7" rgb2="0 0 0"
             width="512" height="3072"/>
    <texture type="2d" name="groundplane" builtin="checker" mark="edge"
             rgb1="0.2 0.3 0.4" rgb2="0.1 0.2 0.3" markrgb="0.8 0.8 0.8"
             width="300" height="300"/>
    <material name="groundplane" texture="groundplane" texuniform="true"
              texrepeat="5 5" reflectance="0.2"/>
  </asset>

  <worldbody>
    <light name="top" pos="0 0 2" mode="trackcom"/>
    <light pos="0 0 1.5" dir="0 0 -1" directional="true"/>
    <geom name="floor" size="0 0 0.05" type="plane" material="groundplane"/>

    <!-- Franka arm link0 (base, fixed to world) -->
    <body name="link0" childclass="panda">
      <inertial mass="0.629769" pos="-0.041018 -0.00014 0.049974"
        fullinertia="0.00315 0.00388 0.004285 8.2904e-7 0.00015 8.2299e-6"/>
      <geom mesh="link0_0" material="off_white" class="visual"/>
      <geom mesh="link0_1" material="black" class="visual"/>
      <geom mesh="link0_2" material="off_white" class="visual"/>
      <geom mesh="link0_3" material="black" class="visual"/>
      <geom mesh="link0_4" material="off_white" class="visual"/>
      <geom mesh="link0_5" material="black" class="visual"/>
      <geom mesh="link0_7" material="white" class="visual"/>
      <geom mesh="link0_8" material="white" class="visual"/>
      <geom mesh="link0_9" material="black" class="visual"/>
      <geom mesh="link0_10" material="off_white" class="visual"/>
      <geom mesh="link0_11" material="white" class="visual"/>
      <geom mesh="link0_c" class="collision"/>

      <!-- link1 -->
      <body name="link1" pos="0 0 0.333">
        <joint name="joint1"/>
        <inertial mass="4.970684" pos="0.003875 0.002081 -0.04762"
          fullinertia="0.70337 0.70661 0.0091170 -0.00013900 0.0067720 0.019169"/>
        <geom material="white" mesh="link1" class="visual"/>
        <geom mesh="link1_c" class="collision"/>

        <!-- link2 (quat -90° X) -->
        <body name="link2" quat="1 -1 0 0">
          <joint name="joint2" range="-1.7628 1.7628"/>
          <inertial mass="0.646926" pos="-0.003141 -0.02872 0.003495"
            fullinertia="0.0079620 2.8110e-2 2.5995e-2 -3.925e-3 1.0254e-2 7.04e-4"/>
          <geom material="white" mesh="link2" class="visual"/>
          <geom mesh="link2_c" class="collision"/>

          <!-- link3 -->
          <body name="link3" pos="0 -0.316 0" quat="1 1 0 0">
            <joint name="joint3"/>
            <inertial mass="3.228604" pos="2.7518e-2 3.9252e-2 -6.6502e-2"
              fullinertia="3.7242e-2 3.6155e-2 1.083e-2 -4.761e-3 -1.1396e-2 -1.2805e-2"/>
            <geom mesh="link3_0" material="white" class="visual"/>
            <geom mesh="link3_1" material="white" class="visual"/>
            <geom mesh="link3_2" material="white" class="visual"/>
            <geom mesh="link3_3" material="black" class="visual"/>
            <geom mesh="link3_c" class="collision"/>

            <!-- link4 -->
            <body name="link4" pos="0.0825 0 0" quat="1 1 0 0">
              <joint name="joint4" range="-3.0718 -0.0698"/>
              <inertial mass="3.587895" pos="-5.317e-2 1.04419e-1 2.7454e-2"
                fullinertia="2.5853e-2 1.9552e-2 2.8323e-2 7.796e-3 -1.332e-3 8.641e-3"/>
              <geom mesh="link4_0" material="white" class="visual"/>
              <geom mesh="link4_1" material="white" class="visual"/>
              <geom mesh="link4_2" material="black" class="visual"/>
              <geom mesh="link4_3" material="white" class="visual"/>
              <geom mesh="link4_c" class="collision"/>

              <!-- link5 -->
              <body name="link5" pos="-0.0825 0.384 0" quat="1 -1 0 0">
                <joint name="joint5"/>
                <inertial mass="1.225946" pos="-1.1953e-2 4.1065e-2 -3.8437e-2"
                  fullinertia="3.5549e-2 2.9474e-2 8.627e-3 -2.117e-3 -4.037e-3 2.29e-4"/>
                <geom mesh="link5_0" material="black" class="visual"/>
                <geom mesh="link5_1" material="white" class="visual"/>
                <geom mesh="link5_2" material="white" class="visual"/>
                <geom mesh="link5_c0" class="collision"/>
                <geom mesh="link5_c1" class="collision"/>
                <geom mesh="link5_c2" class="collision"/>

                <!-- link6 -->
                <body name="link6" quat="1 1 0 0">
                  <joint name="joint6" range="-0.0175 3.7525"/>
                  <inertial mass="1.666555" pos="6.0149e-2 -1.4117e-2 -1.0517e-2"
                    fullinertia="1.964e-3 4.354e-3 5.433e-3 1.09e-4 -1.158e-3 3.41e-4"/>
                  <geom mesh="link6_0" material="off_white" class="visual"/>
                  <geom mesh="link6_1" material="white" class="visual"/>
                  <geom mesh="link6_2" material="black" class="visual"/>
                  <geom mesh="link6_3" material="white" class="visual"/>
                  <geom mesh="link6_4" material="white" class="visual"/>
                  <geom mesh="link6_5" material="white" class="visual"/>
                  <geom mesh="link6_6" material="white" class="visual"/>
                  <geom mesh="link6_7" material="light_blue" class="visual"/>
                  <geom mesh="link6_8" material="light_blue" class="visual"/>
                  <geom mesh="link6_9" material="black" class="visual"/>
                  <geom mesh="link6_10" material="black" class="visual"/>
                  <geom mesh="link6_11" material="white" class="visual"/>
                  <geom mesh="link6_12" material="green" class="visual"/>
                  <geom mesh="link6_13" material="white" class="visual"/>
                  <geom mesh="link6_14" material="black" class="visual"/>
                  <geom mesh="link6_15" material="black" class="visual"/>
                  <geom mesh="link6_16" material="white" class="visual"/>
                  <geom mesh="link6_c" class="collision"/>

                  <!-- link7 (flange) -->
                  <body name="link7" pos="0.088 0 0" quat="1 1 0 0">
                    <joint name="joint7"/>
                    <inertial mass="7.35522e-01" pos="1.0517e-2 -4.252e-3 6.1597e-2"
                      fullinertia="1.2516e-2 1.0027e-2 4.815e-3 -4.28e-4 -1.196e-3 -7.41e-4"/>
                    <geom mesh="link7_0" material="white" class="visual"/>
                    <geom mesh="link7_1" material="black" class="visual"/>
                    <geom mesh="link7_2" material="black" class="visual"/>
                    <geom mesh="link7_3" material="black" class="visual"/>
                    <geom mesh="link7_4" material="black" class="visual"/>
                    <geom mesh="link7_5" material="black" class="visual"/>
                    <geom mesh="link7_6" material="black" class="visual"/>
                    <geom mesh="link7_7" material="white" class="visual"/>
                    <geom mesh="link7_c" class="collision"/>

                    <!-- ===== tendon gripper replaces the stock Franka hand ===== -->
                    <body name="hand" pos="0 0 0.107" quat="0.9238795 0 0 -0.3826834">
                      <inertial mass="0.73" pos="-0.010000 0.000000 0.030000"
                                diaginertia="0.001000 0.002500 0.001700"/>
                      <!-- IK grasp center — midpoint between the two fingertips -->
                      <site name="grasp_center" pos="0 0 0.1204" size="0.005" rgba="1 0 0 1"/>

                      <!-- Finger A (at +Y in hand frame, rotated 90° about Y) -->
                      <body name="a_base" pos="0.000000 0.050000 0.000000" quat="0.707107 0.000000 0.707107 0.000000">
                        <geom type="box" size="0.010000 0.010 0.0075" pos="0.022500 0 0"
                              rgba="0.30 0.30 0.33 1" contype="0" conaffinity="0" density="0" mass="0"/>
                        <body name="a_proximal" pos="0.012500 0.000000 0.000000">
                          <joint name="a_mcp" stiffness="1.0" damping="0.08" range="-0.52360 1.57080"/>
                          <inertial pos="-0.026251 0.000034 -0.000000" mass="0.020000" fullinertia="1.215421e-06 4.532059e-06 4.431324e-06 2.072062e-08 1.045668e-13 -6.640057e-15"/>
                          <geom class="phalanx_vis" mesh="proximal_mesh"/>
                          <geom name="a_proximal_pad" class="phalanx_pad" size="0.027 0.014 0.007" pos="-0.02775 0 0"/>
                          <body name="a_middle" pos="-0.055500 0.000000 0.000000">
                            <joint name="a_pip" stiffness="1.0" damping="0.08" range="-0.52360 1.57080"/>
                            <inertial pos="-0.020253 0.000089 -0.000000" mass="0.016900" fullinertia="5.818377e-07 1.279118e-06 1.195905e-06 8.658681e-09 3.662567e-14 -3.664415e-15"/>
                            <geom class="phalanx_vis" mesh="middle_mesh"/>
                            <geom name="a_middle_pad" class="phalanx_pad" size="0.020 0.012 0.006" pos="-0.0208 0 0"/>
                            <body name="a_distal" pos="-0.041600 0.000000 0.000000">
                              <joint name="a_dip" stiffness="1.0" damping="0.08" range="-0.52360 1.57080"/>
                              <inertial pos="-0.016047 -0.000800 0.000000" mass="0.013700" fullinertia="3.462849e-07 5.280969e-07 4.537598e-07 -4.185637e-08 -5.976719e-15 -1.203437e-14"/>
                              <geom class="phalanx_vis" mesh="distal_mesh"/>
                              <geom name="a_distal_pad" class="phalanx_pad" size="0.017 0.010 0.005" pos="-0.0179 0 0"/>
                              <site name="a_tip" pos="-0.035799 0.000000 0.000000" size="0.001" rgba="0.2 0.7 0.95 1"/>
                            </body>
                          </body>
                        </body>
                      </body>

                      <!-- Finger B (at -Y in hand frame) -->
                      <body name="b_base" pos="0.000000 -0.050000 0.000000" quat="0.000000 -0.707107 0.000000 0.707107">
                        <geom type="box" size="0.010000 0.010 0.0075" pos="0.022500 0 0"
                              rgba="0.30 0.30 0.33 1" contype="0" conaffinity="0" density="0" mass="0"/>
                        <body name="b_proximal" pos="0.012500 0.000000 0.000000">
                          <joint name="b_mcp" stiffness="1.0" damping="0.08" range="-0.52360 1.57080"/>
                          <inertial pos="-0.026251 0.000034 -0.000000" mass="0.020000" fullinertia="1.215421e-06 4.532059e-06 4.431324e-06 2.072062e-08 1.045668e-13 -6.640057e-15"/>
                          <geom class="phalanx_vis" mesh="proximal_mesh"/>
                          <geom name="b_proximal_pad" class="phalanx_pad" size="0.027 0.014 0.007" pos="-0.02775 0 0"/>
                          <body name="b_middle" pos="-0.055500 0.000000 0.000000">
                            <joint name="b_pip" stiffness="1.0" damping="0.08" range="-0.52360 1.57080"/>
                            <inertial pos="-0.020253 0.000089 -0.000000" mass="0.016900" fullinertia="5.818377e-07 1.279118e-06 1.195905e-06 8.658681e-09 3.662567e-14 -3.664415e-15"/>
                            <geom class="phalanx_vis" mesh="middle_mesh"/>
                            <geom name="b_middle_pad" class="phalanx_pad" size="0.020 0.012 0.006" pos="-0.0208 0 0"/>
                            <body name="b_distal" pos="-0.041600 0.000000 0.000000">
                              <joint name="b_dip" stiffness="1.0" damping="0.08" range="-0.52360 1.57080"/>
                              <inertial pos="-0.016047 -0.000800 0.000000" mass="0.013700" fullinertia="3.462849e-07 5.280969e-07 4.537598e-07 -4.185637e-08 -5.976719e-15 -1.203437e-14"/>
                              <geom class="phalanx_vis" mesh="distal_mesh"/>
                              <geom name="b_distal_pad" class="phalanx_pad" size="0.017 0.010 0.005" pos="-0.0179 0 0"/>
                              <site name="b_tip" pos="-0.035799 0.000000 0.000000" size="0.001" rgba="0.2 0.7 0.95 1"/>
                            </body>
                          </body>
                        </body>
                      </body>
                    </body>

                  </body>
                </body>
              </body>
            </body>
          </body>
        </body>
      </body>
    </body>

    <!-- table platform -->
    <body name="table" pos="0.50 0.0 0.0">
      <geom type="box" size="0.05 0.05 0.075" rgba="0.4 0.3 0.2 1"
            solimp="0.95 0.99 0.001" solref="0.005 1"/>
    </body>

    <!-- cube to pick — 35 mm, on the platform -->
    <body name="cube" pos="0.50 0.0 0.0925" childclass="panda">
      <freejoint/>
      <geom name="cube_geom" type="box" size="0.0175 0.0175 0.0175" mass="0.010"
            friction="6.0 6.0 0.05"
            rgba="0.2 0.6 0.9 1" solimp="0.99 0.999 0.001" solref="0.0005 1"/>
    </body>

    <!-- bucket — thin-walled box without top, placed to the side -->
    <body name="bucket" pos="0.30 -0.40 0.0">
      <geom type="box" size="0.075 0.075 0.002" pos="0 0 0.002"
            rgba="0.35 0.25 0.15 1" solimp="0.95 0.99 0.001" solref="0.005 1"/>
      <geom type="box" size="0.002 0.075 0.05" pos="0.075 0 0.052"
            rgba="0.35 0.25 0.15 1"/>
      <geom type="box" size="0.002 0.075 0.05" pos="-0.075 0 0.052"
            rgba="0.35 0.25 0.15 1"/>
      <geom type="box" size="0.075 0.002 0.05" pos="0 0.075 0.052"
            rgba="0.35 0.25 0.15 1"/>
      <geom type="box" size="0.075 0.002 0.05" pos="0 -0.075 0.052"
            rgba="0.35 0.25 0.15 1"/>
    </body>
  </worldbody>

  <tendon>
    <fixed name="a_flexor" stiffness="100000.0" damping="6.0" springlength="-1">
      <joint joint="a_mcp" coef="-0.007"/>
      <joint joint="a_pip" coef="-0.007"/>
      <joint joint="a_dip" coef="-0.007"/>
    </fixed>
    <fixed name="b_flexor" stiffness="100000.0" damping="6.0" springlength="-1">
      <joint joint="b_mcp" coef="-0.007"/>
      <joint joint="b_pip" coef="-0.007"/>
      <joint joint="b_dip" coef="-0.007"/>
    </fixed>
  </tendon>

  <actuator>
    <general class="panda" name="actuator1" joint="joint1" gainprm="4500" biasprm="0 -4500 -450"/>
    <general class="panda" name="actuator2" joint="joint2" gainprm="4500" biasprm="0 -4500 -450"
      ctrlrange="-1.7628 1.7628"/>
    <general class="panda" name="actuator3" joint="joint3" gainprm="3500" biasprm="0 -3500 -350"/>
    <general class="panda" name="actuator4" joint="joint4" gainprm="3500" biasprm="0 -3500 -350"
      ctrlrange="-3.0718 -0.0698"/>
    <general class="panda" name="actuator5" joint="joint5" gainprm="2000" biasprm="0 -2000 -200" forcerange="-12 12"/>
    <general class="panda" name="actuator6" joint="joint6" gainprm="2000" biasprm="0 -2000 -200" forcerange="-12 12"
      ctrlrange="-0.0175 3.7525"/>
    <general class="panda" name="actuator7" joint="joint7" gainprm="2000" biasprm="0 -2000 -200" forcerange="-12 12"/>
  </actuator>

  <contact>
    <exclude body1="a_proximal" body2="a_middle"/>
    <exclude body1="a_middle" body2="a_distal"/>
    <exclude body1="a_proximal" body2="a_distal"/>
    <exclude body1="b_proximal" body2="b_middle"/>
    <exclude body1="b_middle" body2="b_distal"/>
    <exclude body1="b_proximal" body2="b_distal"/>
  </contact>

  <keyframe>
    <key name="home" qpos="0 0 0 -1.57079 0 1.57079 -0.7853 0 0 0 0 0 0"
         ctrl="0 0 0 -1.57079 0 1.57079 -0.7853"/>
  </keyframe>
</mujoco>
